Workbook
Name Deal_Type: List!$A$1:$A$4
Name Deat_Type: #REF!
Name Employee: List!$O$1:$O$16
Name Quater: List!$B$19:$B$26

Sheet List
A1: Self-Prospected | F1: Reorder/resupply | K1: Commercial Director | L1: Gerardo Garcia | M1: Sales Engineer | N1: Carlos Tarazon | O1: Carlos T
A2: New Opportunity | D2: Self-Prospected | E2: New Opportunity | F2: Renewal | H2: Contract | M2: Sales Engineer | N2: Diego Martinez | O2: Diego M
A3: Renewal | C3: Sales Rep | D3: 0.03 | E3: 0.03 | F3: 0.01 | G3: Client/Team | H3: 0 | M3: Sales Engineer | N3: Dulce Ramirez | O3: Dulce R
A4: Contract | C4: KAS | D4: 0.03 | E4: 0.02 | F4: 0.005 | G4: Client/Team | H4: 0 | M4: Sales Engineer | N4: Oziel Garcia | O4: Oziel G
C5: App Eng (AE) | D5: 0.03 | E5: 0.02 | F5: 0.01 | G5: Over 10% net Profit | H5: 0 | K5: Application Manager | L5: Ian Trottier | M5: Applications Engineer/Site Manager | N5: Amanda Quiao | O5: Amanda Q
C6: FST | D6: 0.03 | E6: 0.01 | F6: 0 | H6: 0 | M6: Applications Engineer | N6: Leriel Reyes | O6: Leriel R
M7: Field Application Engineer | N7: Vacancy | O7: Vacancy
F8: 0.02 | G8: total Sales | M8: Applications Engineer | N8: Eduardo Talamantes | O8: Eduardo T
A9: New Companies 2025 | B9: mgr | C9: SALES | D9: 0.015 | K9: Sales Fullfilment Manager | L9: Marlene Martinez | M9: Service Technician | N9: Martin Calderon | O9: Martin C
A10: Freight Revenue | B10: mgr | C10: KAS | D10: 0.015 | M10: Key Account Specialist | N10: Alexis Gil | O10: Alexis G
B11: mgr | C11: APP | D11: 0.015 | M11: Key Account Specialist | N11: Wilka Nunez | O11: Wilka N
M12: Key Account Specialist | N12: Aleksandar Stankovic | O12: Aleksandar S
L13: Mariela de Jesus | M13: Field Service Engineer | N13: Pierre Dupuis | O13: Pierre D
N14: Ian Trottier | O14: Ian T
N15: Marlen Martinez | O15: Marlen M
A16: Dynapro_Commission_Policies_Slides.pptx | N16: Other | O16: Other
B19: 2501 | C19: Q1 2025
B20: 2502 | C20: Q2 2025
B21: 2503 | C21: Q3 2025
B22: 2504 | C22: Q4 2025
B23: 2601 | C23: Q1 2026
B24: 2602 | C24: Q2 2026
B25: 2603 | C25: Q3 2026
B26: 2604 | C26: Q4 2026
A39: Clients | B39: Sales P
A40: AGM Inc. | B40: Amanda Q
A41: Zijin Mining - Rosebel Goldmines N.V. | B41: Amanda Q
A42: Zijin Mining - Rosebel Goldmines N.V., Rosebel Gold Mines N.V. | B42: Amanda Q
A43: Mill-Right Mine Services Inc. | B43: Amanda Q
A44: First Bauxite Inc. | B44: Amanda Q

Sheet rate
A1: Divisa | B1: USD
A3: Row Labels | B3: Average of Tasa de divisa
A4: 1 | B4: 0.69467811
A5: 2 | B5: 0.7022845
A6: 3 | B6: 0.70001794
A7: 4 | B7: 0.71666178
A8: 5 | B8: 0.72192522
A9: 6 | B9: 0.73037887
A10: 7 | B10: 0.72955786
A11: 8 | B11: 0.72425848
A12: 9 | B12: 0.72208412
A13: 10 | B13: 0.71521853
A14: 11 | B14: 0.71452838
A15: 12 | B15: 0.72380448
A16: Grand Total | B16: 0.71631822

Sheet CASO
A1: Número de facturas | B1: Referencia de la orden | C1: Reference | D1: Cliente | E1: Fecha de creación | F1: Fecha de la orden | G1: Shipping Date | H1: Vendedor | I1: Divisa | J1: Tasa de divisa | K1: Total CAD | L1: Total MXP | M1: Total USD | N1: Importe sin impuestos | O1: Impuestos | P1: Total | Q1: Delivery Status | R1: Hubspot Deal Owner | S1: CASOPOInv | T1: Month Created
A2: 1 | B2: SO16348 | C2: 6500015792 | D2: Wesdome Gold Mines Ltd - Eagle River Mine | E2: 45659.4 | F2: 45663.596 | G2: 45664 | H2: Ian Trottier | I2: CAD | J2: 1 | K2: 20655.24 | L2: 0 | M2: 14381.876 | N2: 18278.97 | O2: 2376.27 | P2: 20655.24 | Q2: Delivered | S2: =VLOOKUP(B2,CASOPOInvCL!$B$1:$D$1600,1,FALSE) -> SO16348 | T2: =MONTH(E2) -> 1
A3: 1 | B3: SO16349 | C3: 2243313 | D3: Zijin Mining - Rosebel Goldmines N.V. | E3: 45659.435 | F3: 45660.647 | G3: 45815 | H3: Amanda Qiao | I3: USD | J3: 0.69331656 | K3: 16788.291 | L3: 0 | M3: 11639.6 | N3: 11639.6 | P3: 11639.6 | Q3: Delivered | S3: =VLOOKUP(B3,CASOPOInvCL!$B$1:$D$1600,1,FALSE) -> SO16349 | T3: =MONTH(E3) -> 1
A4: 1 | B4: SO16350 | C4: 4560061462 | D4: Alamos Gold Inc, Alamos Gold Inc Island Gold Division | E4: 45659.437 | F4: 45659.439 | G4: 45670 | H4: Ian Trottier | I4: CAD | J4: 1 | K4: 1540.6 | L4: 0 | M4: 1068.1235 | N4: 1363.36 | O4: 177.24 | P4: 1540.6 | Q4: Delivered | S4: =VLOOKUP(B4,CASOPOInvCL!$B$1:$D$1600,1,FALSE) -> SO16350 | T4: =MONTH(E4) -> 1
A5: 1 | B5: SO16353 | C5: PO-007646 | D5: Sling-Choker Manufacturing - Timmins | E5: 45659.574 | F5: 45659.707 | G5: 45673 | H5: Ian Trottier | I5: CAD | J5: 1 | K5: 2369.71 | L5: 0 | M5: 1642.9592 | N5: 2097.09 | O5: 272.62 | P5: 2369.71 | Q5: Delivered | S5: =VLOOKUP(B5,CASOPOInvCL!$B$1:$D$1600,1,FALSE) -> SO16353 | T5: =MONTH(E5) -> 1
A6: 1 | B6: SO16359 | C6: 5334612 | D6: Corrosion Fluid Products Corp., Corrosion Fluid Products Corp. - Chicago | E6: 45663.493 | F6: 45664.592 | G6: 45665 | H6: Ian Trottier | I6: USD | J6: 0.69628222 | K6: 144.20877 | L6: 0 | M6: 100.41 | N6: 100.41 | P6: 100.41 | Q6: Delivered | S6: =VLOOKUP(B6,CASOPOInvCL!$B$1:$D$1600,1,FALSE) -> SO16359 | T6: =MONTH(E6) -> 1
A7: 1 | B7: SO16360 | C7: 6633 | D7: Hyperflo | E7: 45663.509 | F7: 45663.583 | G7: 45664 | H7: Ian Trottier | I7: CAD | J7: 1 | K7: 1006.02 | L7: 0 | M7: 700.47384 | N7: 958.11 | O7: 47.91 | P7: 1006.02 | Q7: Delivered | S7: =VLOOKUP(B7,CASOPOInvCL!$B$1:$D$1600,1,FALSE) -> SO16360 | T7: =MONTH(E7) -> 1
A8: 1 | B8: SO16361 | C8: 007673 | D8: Sling-Choker Manufacturing - Timmins | E8: 45663.524 | F8: 45673.552 | G8: 45750 | H8: Ian Trottier | I8: CAD | J8: 1 | K8: 29994.38 | L8: 0 | M8: 20856.609 | N8: 26543.7 | O8: 3450.68 | P8: 29994.38 | Q8: Delivered | S8: =VLOOKUP(B8,CASOPOInvCL!$B$1:$D$1600,1,FALSE) -> SO16361 | T8: =MONTH(E8) -> 1
A9: 1 | B9: SO16362 | C9: P349617 | D9: Covia Corp - Junction City | E9: 45663.531 | F9: 45664.582 | G9: 45665 | H9: Marlen Martinez | I9: CAD | J9: 1 | K9: 8795 | L9: 0 | M9: 6131.3693 | N9: 8795 | P9: 8795 | Q9: Delivered | S9: =VLOOKUP(B9,CASOPOInvCL!$B$1:$D$1600,1,FALSE) -> SO16362 | T9: =MONTH(E9) -> 1
A10: 1 | B10: SO16363 | C10: 2961 | D10: Les Pompes du St-Laurent Inc. | E10: 45663.564 | F10: 45663.565 | G10: 45698 | H10: Ian Trottier | I10: CAD | J10: 1 | K10: 1135.51 | L10: 0 | M10: 790.63542 | N10: 1081.44 | O10: 54.07 | P10: 1135.51 | Q10: Delivered | S10: =VLOOKUP(B10,CASOPOInvCL!$B$1:$D$1600,1,FALSE) -> SO16363 | T10: =MONTH(E10) -> 1
A11: 1 | B11: SO16364 | C11: 003247 | D11: Eleazar General & Industrial Supplies Limited | E11: 45663.57 | F11: 45667.613 | G11: 45751 | H11: Ian Trottier | I11: USD | J11: 0.69455773 | K11: 1896.8762 | L11: 0 | M11: 1317.49 | N11: 1317.49 | P11: 1317.49 | Q11: Delivered | S11: =VLOOKUP(B11,CASOPOInvCL!$B$1:$D$1600,1,FALSE) -> SO16364 | T11: =MONTH(E11) -> 1
A12: 1 | B12: SO16368 | C12: M-083469 | D12: Grant Aggregate | E12: 45663.694 | F12: 45666.408 | G12: 45667 | H12: Ian Trottier | I12: CAD | J12: 1 | K12: 17048.1 | L12: 0 | M12: 11840.89 | N12: 15086.8 | O12: 1961.3 | P12: 17048.1 | Q12: Delivered | S12: =VLOOKUP(B12,CASOPOInvCL!$B$1:$D$1600,1,FALSE) -> SO16368 | T12: =MONTH(E12) -> 1
A13: 1 | B13: SO16369 | C13: PO13146 | D13: Manufacture Sling-Choker (Val-d’Or) Ltée | E13: 45664.409 | F13: 45664.622 | G13: 45665 | H13: Ian Trottier | I13: CAD | J13: 1 | K13: 117.99 | L13: 0 | M13: 82.255857 | N13: 112.37 | O13: 5.62 | P13: 117.99 | Q13: Delivered | S13: =VLOOKUP(B13,CASOPOInvCL!$B$1:$D$1600,1,FALSE) -> SO16369 | T13: =MONTH(E13) -> 1
A14: 1 | B14: SO16372 | C14: 2991 | D14: Les Pompes du St-Laurent Inc. | E14: 45664.491 | F14: 45673.632 | G14: 45720 | H14: Ian Trottier | I14: CAD | J14: 1 | K14: 1657.93 | L14: 0 | M14: 1152.8426 | N14: 1578.98 | O14: 78.95 | P14: 1657.93 | Q14: Delivered | S14: =VLOOKUP(B14,CASOPOInvCL!$B$1:$D$1600,1,FALSE) -> SO16372 | T14: =MONTH(E14) -> 1
A15: 1 | B15: SO16374 | C15: 2967 | D15: Les Pompes du St-Laurent Inc. | E15: 45664.533 | F15: 45665.677 | G15: 45666 | H15: Ian Trottier | I15: CAD | J15: 1 | K15: 3783.15 | L15: 0 | M15: 2631.4956 | N15: 3603 | O15: 180.15 | P15: 3783.15 | Q15: Delivered | S15: =VLOOKUP(B15,CASOPOInvCL!$B$1:$D$1600,1,FALSE) -> SO16374 | T15: =MONTH(E15) -> 1
A16: 1 | B16: SO16375 | C16: P349794 | D16: Covia Corp - Junction City | E16: 45664.545 | F16: 45665.577 | G16: 45666 | H16: Marlen Martinez | I16: CAD | J16: 1 | K16: 5506 | L16: 0 | M16: 3829.8811 | N16: 5506 | P16: 5506 | Q16: Delivered | S16: =VLOOKUP(B16,CASOPOInvCL!$B$1:$D$1600,1,FALSE) -> SO16375 | T16: =MONTH(E16) -> 1
A17: 1 | B17: SO16376 | C17: 007656 | D17: Sling-Choker Manufacturing - Timmins | E17: 45664.556 | F17: 45664.682 | G17: 45326 | H17: Ian Trottier | I17: CAD | J17: 1 | K17: 13951.67 | L17: 0 | M17: 9726.3036 | N17: 12346.61 | O17: 1605.06 | P17: 13951.67 | Q17: Delivered | S17: =VLOOKUP(B17,CASOPOInvCL!$B$1:$D$1600,1,FALSE) -> SO16376 | T17: =MONTH(E17) -> 1
A18: 1 | B18: SO16377 | C18: 316223 | D18: Gibraltar Mine (Canada) | E18: 45664.681 | F18: 45664.716 | G18: 45706 | H18: Ian Trottier | I18: CAD | J18: 1 | K18: 5367.86 | L18: 0 | M18: 3742.1639 | N18: 5112.25 | O18: 255.61 | P18: 5367.86 | Q18: Delivered | S18: =VLOOKUP(B18,CASOPOInvCL!$B$1:$D$1600,1,FALSE) -> SO16377 | T18: =MONTH(E18) -> 1
A19: 1 | B19: SO16378 | C19: BC78-00052101 | D19: Motion Industries Inc. (Canada) - Quesnel | E19: 45664.694 | F19: 45665.391 | G19: 45693 | H19: Ian Trottier | I19: CAD | J19: 1 | K19: 1036.94 | L19: 0 | M19: 721.27805 | N19: 987.57 | O19: 49.37 | P19: 1036.94 | Q19: Delivered | S19: =VLOOKUP(B19,CASOPOInvCL!$B$1:$D$1600,1,FALSE) -> SO16378 | T19: =MONTH(E19) -> 1
A20: 1 | B20: SO16379 | C20: PO-007657 | D20: Sling-Choker Manufacturing - Timmins | E20: 45665.302 | F20: 45665.377 | G20: 45665 | H20: Taylor Cook | I20: CAD | J20: 1 | K20: 2007.42 | L20: 0 | M20: 1396.3276 | N20: 1776.49 | O20: 230.93 | P20: 2007.42 | Q20: Delivered | S20: =VLOOKUP(B20,CASOPOInvCL!$B$1:$D$1600,1,FALSE) -> SO16379 | T20: =MONTH(E20) -> 1
A21: 3 | B21: SO16380 | C21: L63079-DS | D21: Wild Rows Pump & Compression LTD. | E21: 45665.427 | F21: 45665.651 | G21: 45777 | H21: Taylor Cook | I21: CAD | J21: 1 | K21: 4153.74 | L21: 0 | M21: 2889.2718 | N21: 3955.95 | O21: 197.79 | P21: 4153.74 | Q21: Delivered | S21: =VLOOKUP(B21,CASOPOInvCL!$B$1:$D$1600,1,FALSE) -> SO16380 | T21: =MONTH(E21) -> 1
A22: 1 | B22: SO16381 | C22: 6642 | D22: Hyperflo | E22: 45665.433 | F22: 45665.477 | G22: 45666 | H22: Ian Trottier | I22: CAD | J22: 1 | K22: 962.42 | L22: 0 | M22: 669.44319 | N22: 916.59 | O22: 45.83 | P22: 962.42 | Q22: Delivered | S22: =VLOOKUP(B22,CASOPOInvCL!$B$1:$D$1600,1,FALSE) -> SO16381 | T22: =MONTH(E22) -> 1
A23: 1 | B23: SO16382 | C23: 071736 | D23: Hoffman-Kane Distributors, Inc. | E23: 45665.456 | F23: 45665.459 | G23: 45666 | H23: Ian Trottier | I23: USD | J23: 0.69714261 | K23: 197.62097 | L23: 0 | M23: 137.77 | N23: 137.77 | P23: 137.77 | Q23: Delivered | S23: =VLOOKUP(B23,CASOPOInvCL!$B$1:$D$1600,1,FALSE) -> SO16382 | T23: =MONTH(E23) -> 1
A24: 1 | B24: SO16383 | C24: 4501080579 | D24: Barrick Gold - Pueblo Viejo Dominicana Corporation | E24: 45665.47 | F24: 45666.818 | G24: 45665 | H24: Jeff Bell | I24: USD | J24: 0.6955832 | K24: 15727.809 | L24: 0 | M24: 10940 | N24: 10940 | P24: 10940 | Q24: Delivered | S24: =VLOOKUP(B24,CASOPOInvCL!$B$1:$D$1600,1,FALSE) -> SO16383 | T24: =MONTH(E24) -> 1
A25: 1 | B25: SO16384 | C25: 2968 | D25: Les Pompes du St-Laurent Inc. | E25: 45665.494 | F25: 45665.681 | G25: 45791 | H25: Ian Trottier | I25: CAD | J25: 1 | K25: 2094.52 | L25: 0 | M25: 1456.9129 | N25: 1994.78 | O25: 99.74 | P25: 2094.52 | Q25: Delivered | S25: =VLOOKUP(B25,CASOPOInvCL!$B$1:$D$1600,1,FALSE) -> SO16384 | T25: =MONTH(E25) -> 1
A26: 1 | B26: SO16385 | C26: 11627 | D26: Les Pompes Diaspec Inc. | E26: 45665.501 | F26: 45686.418 | G26: 45687 | H26: Ian Trottier | I26: CAD | J26: 1 | K26: 12217.92 | L26: 12217.92 | M26: 12217.92 | N26: 11636.11 | O26: 581.81 | P26: 12217.92 | Q26: Delivered | S26: =VLOOKUP(B26,CASOPOInvCL!$B$1:$D$1600,1,FALSE) -> SO16385 | T26: =MONTH(E26) -> 1
A27: 1 | B27: SO16389 | C27: 6645 | D27: Hyperflo | E27: 45665.569 | F27: 45665.636 | G27: 45666 | H27: Taylor Cook | I27: CAD | J27: 1 | K27: 224.6 | L27: 0 | M27: 156.22799 | N27: 213.9 | O27: 10.7 | P27: 224.6 | Q27: Delivered | S27: =VLOOKUP(B27,CASOPOInvCL!$B$1:$D$1600,1,FALSE) -> SO16389 | T27: =MONTH(E27) -> 1
A28: 2 | B28: SO16390 | C28: 2969 | D28: Les Pompes du St-Laurent Inc. | E28: 45665.671 | F28: 45665.674 | G28: 45688 | H28: Ian Trottier | I28: CAD | J28: 1 | K28: 972.43 | L28: 0 | M28: 676.40597 | N28: 926.12 | O28: 46.31 | P28: 972.43 | Q28: Delivered | S28: =VLOOKUP(B28,CASOPOInvCL!$B$1:$D$1600,1,FALSE) -> SO16390 | T28: =MONTH(E28) -> 1
A29: 1 | B29: SO16392 | C29: 4500574897 | D29: Resolute Forest Products - Kenogami | E29: 45666.438 | F29: 45671.64 | G29: 45744 | H29: Ian Trottier | I29: CAD | J29: 1 | K29: 7778.54 | L29: 0 | M29: 5412.4629 | N29: 7408.13 | O29: 370.41 | P29: 7778.54 | Q29: Delivered | S29: =VLOOKUP(B29,CASOPOInvCL!$B$1:$D$1600,1,FALSE) -> SO16392 | T29: =MONTH(E29) -> 1
A30: 2 | B30: SO16393 | C30: 2051 | D30: FMI Products | E30: 45666.497 | F30: 45671.44 | G30: 45706 | H30: Ian Trottier | I30: CAD | J30: 1 | K30: 2482.17 | L30: 0 | M30: 1727.1433 | N30: 2363.97 | O30: 118.2 | P30: 2482.17 | Q30: Delivered | S30: =VLOOKUP(B30,CASOPOInvCL!$B$1:$D$1600,1,FALSE) -> SO16393 | T30: =MONTH(E30) -> 1
A31: 1 | B31: SO16397 | C31: 5345945 | D31: Corrosion Fluid Products Corp. | E31: 45666.711 | F31: 45719.694 | G31: 45733 | H31: Ian Trottier | I31: USD | J31: 0.69136666 | K31: 1339.7088 | L31: 0 | M31: 926.23 | N31: 926.23 | P31: 926.23 | Q31: Delivered | S31: =VLOOKUP(B31,CASOPOInvCL!$B$1:$D$1600,1,FALSE) -> SO16397 | T31: =MONTH(E31) -> 1
A32: 1 | B32: SO16399 | C32: 08840 | D32: Tantalum Mining Corporation of Canada | E32: 45667.393 | F32: 45672.575 | G32: 45673 | H32: Taylor Cook | I32: CAD | J32: 1 | K32: 904.12 | L32: 904.12 | M32: 904.12 | N32: 861.07 | O32: 43.05 | P32: 904.12 | Q32: Delivered | S32: =VLOOKUP(B32,CASOPOInvCL!$B$1:$D$1600,1,FALSE) -> SO16399 | T32: =MONTH(E32) -> 1
A33: 1 | B33: SO16400 | C33: 9569096 | D33: DXP Enterprises, Inc. - Pumping Solutions, Inc. - Hayward California | E33: 45667.397 | F33: 45672.521 | G33: 45707 | H33: Taylor Cook | I33: USD | J33: 0.6958199 | K33: 3105.4444 | L33: 0 | M33: 2160.83 | N33: 2160.83 | P33: 2160.83 | Q33: Delivered | S33: =VLOOKUP(B33,CASOPOInvCL!$B$1:$D$1600,1,FALSE) -> SO16400 | T33: =MONTH(E33) -> 1
A34: 1 | B34: SO16401 | C34: FC10-00114698 | D34: Motion Industries Inc. (U.S.) - Lakeland | E34: 45667.413 | F34: 45670.587 | G34: 45671 | H34: Taylor Cook | I34: USD | J34: 0.69462239 | K34: 120.92901 | L34: 0 | M34: 84 | N34: 84 | P34: 84 | Q34: Delivered | S34: =VLOOKUP(B34,CASOPOInvCL!$B$1:$D$1600,1,FALSE) -> SO16401 | T34: =MONTH(E34) -> 1
A35: 1 | B35: SO16402 | C35: 2243614 | D35: Zijin Mining - Rosebel Goldmines N.V. | E35: 45667.485 | F35: 45670.436 | G35: 45710 | H35: Amanda Qiao | I35: USD | J35: 0.69462239 | K35: 5373.711 | L35: 0 | M35: 3732.7 | N35: 3732.7 | P35: 3732.7 | Q35: Delivered | S35: =VLOOKUP(B35,CASOPOInvCL!$B$1:$D$1600,1,FALSE) -> SO16402 | T35: =MONTH(E35) -> 1
A36: 1 | B36: SO16403 | C36: MB21-00185834 | D36: Motion Industries Inc. (Canada) - Winnipeg | E36: 45667.524 | F36: 45667.608 | G36: 45670 | H36: Taylor Cook | I36: CAD | J36: 1 | K36: 540.3 | L36: 0 | M36: 374.24329 | N36: 540.3 | P36: 540.3 | Q36: Delivered | S36: =VLOOKUP(B36,CASOPOInvCL!$B$1:$D$1600,1,FALSE) -> SO16403 | T36: =MONTH(E36) -> 1
A37: 1 | B37: SO16405 | C37: 2100484115 | D37: Wajax Limited - Sorel-Tracy | E37: 45667.625 | F37: 45667.701 | G37: 45670 | H37: Taylor Cook | I37: CAD | J37: 1 | K37: 2138.66 | L37: 0 | M37: 1481.3607 | N37: 2036.82 | O37: 101.84 | P37: 2138.66 | Q37: Delivered | S37: =VLOOKUP(B37,CASOPOInvCL!$B$1:$D$1600,1,FALSE) -> SO16405 | T37: =MONTH(E37) -> 1
A38: 1 | B38: SO16406 | C38: 2981 | D38: Les Pompes du St-Laurent Inc. | E38: 45667.649 | F38: 45670.593 | G38: 45698 | H38: Ian Trottier | I38: CAD | J38: 1 | K38: 2358.51 | L38: 0 | M38: 1636.6784 | N38: 2246.2 | O38: 112.31 | P38: 2358.51 | Q38: Delivered | S38: =VLOOKUP(B38,CASOPOInvCL!$B$1:$D$1600,1,FALSE) -> SO16406 | T38: =MONTH(E38) -> 1
A39: 1 | B39: SO16408 | C39: P-11425 | D39: Cartledge & Associates Inc. | E39: 45670.403 | F39: 45671.538 | G39: 45672 | H39: Ian Trottier | I39: USD | J39: 0.6939459 | K39: 4614.279 | L39: 0 | M39: 3202.06 | N39: 3202.06 | P39: 3202.06 | Q39: Delivered | S39: =VLOOKUP(B39,CASOPOInvCL!$B$1:$D$1600,1,FALSE) -> SO16408 | T39: =MONTH(E39) -> 1
A40: 1 | B40: SO16409 | C40: PO-038220 | D40: Southeast Pump Specialist, Inc. | E40: 45670.409 | F40: 45670.43 | G40: 45671 | H40: Ian Trottier | I40: USD | J40: 0.69462239 | K40: 4344.1589 | L40: 0 | M40: 3017.55 | N40: 3017.55 | P40: 3017.55 | Q40: Delivered | S40: =VLOOKUP(B40,CASOPOInvCL!$B$1:$D$1600,1,FALSE) -> SO16409 | T40: =MONTH(E40) -> 1
...

Sheet InvBal
A1: Zero | B1: XX
F3: Values
A4: SO | B4: INV | C4: Client | D4: Curr | E4: Paid | F4: Odoo CAD | G4: Odoo USA | H4: Xero CAD | I4: Xero USD | J4: Cur | K4: Len | L4: SO 1 | M4: CAD | N4: USD | O4: Paid | P4: Freight | Q4: Yes Two
A5: SO16380 | B5: INV12496 | C5: Wild Rows Pump & Compression LTD. | D5: CAD | E5: Yes | F5: 3955.95 | G5: 2751.6924 | H5: -1827.63 | I5: 0 | J5: =IF(K5=13,D4,"") | K5: =LEN(A5) -> 7 | L5: =IF(K5=13,LEFT(A5,7),"") | M5: =IF(AND(K5=13,D4="CAD"),ROUND(F5+H5,2),0) -> 0 | N5: =IF(AND(K5=13,D4="USD"),ROUND(G5+I5,2),0) -> 0 | O5: =IF(K5=13,IF(M5+N5=0,"Yes",0),0) -> 0 | P5: =IFERROR(VLOOKUP(B5,'Receivable Invoice Detail'!$S$1:$U$3014,3,FALSE),0) -> 0
B6: INV12584 | C6: Wild Rows Pump & Compression LTD. | D6: CAD | E6: Yes | F6: 0 | G6: 0 | H6: -857.76 | I6: 0 | J6: =IF(K6=13,D5,"") | K6: =LEN(A6) -> 0 | L6: =IF(K6=13,LEFT(A6,7),"") | M6: =IF(AND(K6=13,D5="CAD"),ROUND(F6+H6,2),0) -> 0 | N6: =IF(AND(K6=13,D5="USD"),ROUND(G6+I6,2),0) -> 0 | O6: =IF(K6=13,IF(M6+N6=0,"Yes",0),0) -> 0 | P6: =IFERROR(VLOOKUP(B6,'Receivable Invoice Detail'!$S$1:$U$3014,3,FALSE),0) -> 0
B7: INV12953 | C7: Wild Rows Pump & Compression LTD. | D7: CAD | E7: Yes | F7: 0 | G7: 0 | H7: -1270.56 | I7: 0 | J7: =IF(K7=13,D6,"") | K7: =LEN(A7) -> 0 | L7: =IF(K7=13,LEFT(A7,7),"") | M7: =IF(AND(K7=13,D6="CAD"),ROUND(F7+H7,2),0) -> 0 | N7: =IF(AND(K7=13,D6="USD"),ROUND(G7+I7,2),0) -> 0 | O7: =IF(K7=13,IF(M7+N7=0,"Yes",0),0) -> 0 | P7: =IFERROR(VLOOKUP(B7,'Receivable Invoice Detail'!$S$1:$U$3014,3,FALSE),0) -> 0
A8: SO16380 Total | F8: 3955.95 | G8: 2751.6924 | H8: -3955.95 | I8: 0 | J8: =IF(K8=13,D7,"") -> CAD | K8: =LEN(A8) -> 13 | L8: =IF(K8=13,LEFT(A8,7),"") -> SO16380 | M8: =IF(AND(K8=13,D7="CAD"),ROUND(F8+H8,2),0) -> 0 | N8: =IF(AND(K8=13,D7="USD"),ROUND(G8+I8,2),0) -> 0 | O8: =IF(K8=13,IF(M8+N8=0,"Yes",0),0) -> Yes | P8: =IFERROR(VLOOKUP(B8,'Receivable Invoice Detail'!$S$1:$U$3014,3,FALSE),0) -> 0
A9: SO16390 | B9: INV12506 | C9: Les Pompes du St-Laurent Inc. | D9: CAD | E9: Yes | F9: 0 | G9: 0 | H9: -463.06 | I9: 0 | J9: =IF(K9=13,D8,"") | K9: =LEN(A9) -> 7 | L9: =IF(K9=13,LEFT(A9,7),"") | M9: =IF(AND(K9=13,D8="CAD"),ROUND(F9+H9,2),0) -> 0 | N9: =IF(AND(K9=13,D8="USD"),ROUND(G9+I9,2),0) -> 0 | O9: =IF(K9=13,IF(M9+N9=0,"Yes",0),0) -> 0 | P9: =IFERROR(VLOOKUP(B9,'Receivable Invoice Detail'!$S$1:$U$3014,3,FALSE),0) -> 0
B10: INV12631 | C10: Les Pompes du St-Laurent Inc. | D10: CAD | E10: Yes | F10: 926.12 | G10: 644.19352 | H10: -463.06 | I10: 0 | J10: =IF(K10=13,D9,"") | K10: =LEN(A10) -> 0 | L10: =IF(K10=13,LEFT(A10,7),"") | M10: =IF(AND(K10=13,D9="CAD"),ROUND(F10+H10,2),0) -> 0 | N10: =IF(AND(K10=13,D9="USD"),ROUND(G10+I10,2),0) -> 0 | O10: =IF(K10=13,IF(M10+N10=0,"Yes",0),0) -> 0 | P10: =IFERROR(VLOOKUP(B10,'Receivable Invoice Detail'!$S$1:$U$3014,3,FALSE),0) -> 0
A11: SO16390 Total | F11: 926.12 | G11: 644.19352 | H11: -926.12 | I11: 0 | J11: =IF(K11=13,D10,"") -> CAD | K11: =LEN(A11) -> 13 | L11: =IF(K11=13,LEFT(A11,7),"") -> SO16390 | M11: =IF(AND(K11=13,D10="CAD"),ROUND(F11+H11,2),0) -> 0 | N11: =IF(AND(K11=13,D10="USD"),ROUND(G11+I11,2),0) -> 0 | O11: =IF(K11=13,IF(M11+N11=0,"Yes",0),0) -> Yes | P11: =IFERROR(VLOOKUP(B11,'Receivable Invoice Detail'!$S$1:$U$3014,3,FALSE),0) -> 0
A12: SO16393 | B12: INV12541 | C12: FMI Products | D12: CAD | E12: Yes | F12: 0 | G12: 0 | H12: -701.83 | I12: 0 | J12: =IF(K12=13,D11,"") | K12: =LEN(A12) -> 7 | L12: =IF(K12=13,LEFT(A12,7),"") | M12: =IF(AND(K12=13,D11="CAD"),ROUND(F12+H12,2),0) -> 0 | N12: =IF(AND(K12=13,D11="USD"),ROUND(G12+I12,2),0) -> 0 | O12: =IF(K12=13,IF(M12+N12=0,"Yes",0),0) -> 0 | P12: =IFERROR(VLOOKUP(B12,'Receivable Invoice Detail'!$S$1:$U$3014,3,FALSE),0) -> 0
B13: INV12704 | C13: FMI Products | D13: CAD | E13: Yes | F13: 2363.97 | G13: 1644.8974 | H13: -1662.14 | I13: 0 | J13: =IF(K13=13,D12,"") | K13: =LEN(A13) -> 0 | L13: =IF(K13=13,LEFT(A13,7),"") | M13: =IF(AND(K13=13,D12="CAD"),ROUND(F13+H13,2),0) -> 0 | N13: =IF(AND(K13=13,D12="USD"),ROUND(G13+I13,2),0) -> 0 | O13: =IF(K13=13,IF(M13+N13=0,"Yes",0),0) -> 0 | P13: =IFERROR(VLOOKUP(B13,'Receivable Invoice Detail'!$S$1:$U$3014,3,FALSE),0) -> 0
A14: SO16393 Total | F14: 2363.97 | G14: 1644.8974 | H14: -2363.97 | I14: 0 | J14: =IF(K14=13,D13,"") -> CAD | K14: =LEN(A14) -> 13 | L14: =IF(K14=13,LEFT(A14,7),"") -> SO16393 | M14: =IF(AND(K14=13,D13="CAD"),ROUND(F14+H14,2),0) -> 0 | N14: =IF(AND(K14=13,D13="USD"),ROUND(G14+I14,2),0) -> 0 | O14: =IF(K14=13,IF(M14+N14=0,"Yes",0),0) -> Yes | P14: =IFERROR(VLOOKUP(B14,'Receivable Invoice Detail'!$S$1:$U$3014,3,FALSE),0) -> 0
A15: SO16438 | B15: INV12550 | C15: Canadian Bearings Ltd. | D15: CAD | E15: Yes | F15: 621.28 | G15: 430.74594 | H15: -587.3 | I15: 0 | J15: =IF(K15=13,D14,"") | K15: =LEN(A15) -> 7 | L15: =IF(K15=13,LEFT(A15,7),"") | M15: =IF(AND(K15=13,D14="CAD"),ROUND(F15+H15,2),0) -> 0 | N15: =IF(AND(K15=13,D14="USD"),ROUND(G15+I15,2),0) -> 0 | O15: =IF(K15=13,IF(M15+N15=0,"Yes",0),0) -> 0 | P15: =IFERROR(VLOOKUP(B15,'Receivable Invoice Detail'!$S$1:$U$3014,3,FALSE),0) -> 0
B16: INV12677 | C16: Canadian Bearings Ltd. | D16: CAD | E16: Yes | F16: 0 | G16: 0 | H16: -33.98 | I16: 0 | J16: =IF(K16=13,D15,"") | K16: =LEN(A16) -> 0 | L16: =IF(K16=13,LEFT(A16,7),"") | M16: =IF(AND(K16=13,D15="CAD"),ROUND(F16+H16,2),0) -> 0 | N16: =IF(AND(K16=13,D15="USD"),ROUND(G16+I16,2),0) -> 0 | O16: =IF(K16=13,IF(M16+N16=0,"Yes",0),0) -> 0 | P16: =IFERROR(VLOOKUP(B16,'Receivable Invoice Detail'!$S$1:$U$3014,3,FALSE),0) -> 0
A17: SO16438 Total | F17: 621.28 | G17: 430.74594 | H17: -621.28 | I17: 0 | J17: =IF(K17=13,D16,"") -> CAD | K17: =LEN(A17) -> 13 | L17: =IF(K17=13,LEFT(A17,7),"") -> SO16438 | M17: =IF(AND(K17=13,D16="CAD"),ROUND(F17+H17,2),0) -> 0 | N17: =IF(AND(K17=13,D16="USD"),ROUND(G17+I17,2),0) -> 0 | O17: =IF(K17=13,IF(M17+N17=0,"Yes",0),0) -> Yes | P17: =IFERROR(VLOOKUP(B17,'Receivable Invoice Detail'!$S$1:$U$3014,3,FALSE),0) -> 0
A18: SO16467 | B18: INV12582 | C18: Wild Rows Pump & Compression LTD. | D18: CAD | E18: Yes | F18: 0 | G18: 0 | H18: -50 | I18: 0 | J18: =IF(K18=13,D17,"") | K18: =LEN(A18) -> 7 | L18: =IF(K18=13,LEFT(A18,7),"") | M18: =IF(AND(K18=13,D17="CAD"),ROUND(F18+H18,2),0) -> 0 | N18: =IF(AND(K18=13,D17="USD"),ROUND(G18+I18,2),0) -> 0 | O18: =IF(K18=13,IF(M18+N18=0,"Yes",0),0) -> 0 | P18: =IFERROR(VLOOKUP(B18,'Receivable Invoice Detail'!$S$1:$U$3014,3,FALSE),0) -> 0
B19: INV12585 | C19: Wild Rows Pump & Compression LTD. | D19: CAD | E19: Yes | F19: 0 | G19: 0 | H19: -129.88 | I19: 0 | J19: =IF(K19=13,D18,"") | K19: =LEN(A19) -> 0 | L19: =IF(K19=13,LEFT(A19,7),"") | M19: =IF(AND(K19=13,D18="CAD"),ROUND(F19+H19,2),0) -> 0 | N19: =IF(AND(K19=13,D18="USD"),ROUND(G19+I19,2),0) -> 0 | O19: =IF(K19=13,IF(M19+N19=0,"Yes",0),0) -> 0 | P19: =IFERROR(VLOOKUP(B19,'Receivable Invoice Detail'!$S$1:$U$3014,3,FALSE),0) -> 0
B20: INV12954 | C20: Wild Rows Pump & Compression LTD. | D20: CAD | E20: Yes | F20: 1026.9 | G20: 716.51446 | H20: -847.02 | I20: 0 | J20: =IF(K20=13,D19,"") | K20: =LEN(A20) -> 0 | L20: =IF(K20=13,LEFT(A20,7),"") | M20: =IF(AND(K20=13,D19="CAD"),ROUND(F20+H20,2),0) -> 0 | N20: =IF(AND(K20=13,D19="USD"),ROUND(G20+I20,2),0) -> 0 | O20: =IF(K20=13,IF(M20+N20=0,"Yes",0),0) -> 0 | P20: =IFERROR(VLOOKUP(B20,'Receivable Invoice Detail'!$S$1:$U$3014,3,FALSE),0) -> 0
A21: SO16467 Total | F21: 1026.9 | G21: 716.51446 | H21: -1026.9 | I21: 0 | J21: =IF(K21=13,D20,"") -> CAD | K21: =LEN(A21) -> 13 | L21: =IF(K21=13,LEFT(A21,7),"") -> SO16467 | M21: =IF(AND(K21=13,D20="CAD"),ROUND(F21+H21,2),0) -> 0 | N21: =IF(AND(K21=13,D20="USD"),ROUND(G21+I21,2),0) -> 0 | O21: =IF(K21=13,IF(M21+N21=0,"Yes",0),0) -> Yes | P21: =IFERROR(VLOOKUP(B21,'Receivable Invoice Detail'!$S$1:$U$3014,3,FALSE),0) -> 0
A22: SO16470 | B22: INV12549 | C22: Resolute Forest Products - Saint-Felicien | D22: CAD | E22: Yes | F22: 1969.52 | G22: 1374.223 | H22: -784.42 | I22: 0 | J22: =IF(K22=13,D21,"") | K22: =LEN(A22) -> 7 | L22: =IF(K22=13,LEFT(A22,7),"") | M22: =IF(AND(K22=13,D21="CAD"),ROUND(F22+H22,2),0) -> 0 | N22: =IF(AND(K22=13,D21="USD"),ROUND(G22+I22,2),0) -> 0 | O22: =IF(K22=13,IF(M22+N22=0,"Yes",0),0) -> 0 | P22: =IFERROR(VLOOKUP(B22,'Receivable Invoice Detail'!$S$1:$U$3014,3,FALSE),0) -> 0
B23: INV12697 | C23: Resolute Forest Products - Saint-Felicien | D23: CAD | E23: Yes | F23: 0 | G23: 0 | H23: -1185.1 | I23: 0 | J23: =IF(K23=13,D22,"") | K23: =LEN(A23) -> 0 | L23: =IF(K23=13,LEFT(A23,7),"") | M23: =IF(AND(K23=13,D22="CAD"),ROUND(F23+H23,2),0) -> 0 | N23: =IF(AND(K23=13,D22="USD"),ROUND(G23+I23,2),0) -> 0 | O23: =IF(K23=13,IF(M23+N23=0,"Yes",0),0) -> 0 | P23: =IFERROR(VLOOKUP(B23,'Receivable Invoice Detail'!$S$1:$U$3014,3,FALSE),0) -> 0
A24: SO16470 Total | F24: 1969.52 | G24: 1374.223 | H24: -1969.52 | I24: 0 | J24: =IF(K24=13,D23,"") -> CAD | K24: =LEN(A24) -> 13 | L24: =IF(K24=13,LEFT(A24,7),"") -> SO16470 | M24: =IF(AND(K24=13,D23="CAD"),ROUND(F24+H24,2),0) -> 0 | N24: =IF(AND(K24=13,D23="USD"),ROUND(G24+I24,2),0) -> 0 | O24: =IF(K24=13,IF(M24+N24=0,"Yes",0),0) -> Yes | P24: =IFERROR(VLOOKUP(B24,'Receivable Invoice Detail'!$S$1:$U$3014,3,FALSE),0) -> 0
A25: SO16476 | B25: INV12578 | C25: Canadian Bearings Ltd. | D25: CAD | E25: Yes | F25: 0 | G25: 0 | H25: -80.04 | I25: 0 | J25: =IF(K25=13,D24,"") | K25: =LEN(A25) -> 7 | L25: =IF(K25=13,LEFT(A25,7),"") | M25: =IF(AND(K25=13,D24="CAD"),ROUND(F25+H25,2),0) -> 0 | N25: =IF(AND(K25=13,D24="USD"),ROUND(G25+I25,2),0) -> 0 | O25: =IF(K25=13,IF(M25+N25=0,"Yes",0),0) -> 0 | P25: =IFERROR(VLOOKUP(B25,'Receivable Invoice Detail'!$S$1:$U$3014,3,FALSE),0) -> 0
B26: INV12614 | C26: Canadian Bearings Ltd. | D26: CAD | E26: Yes | F26: 2121.09 | G26: 1473.6664 | H26: -2041.05 | I26: 0 | J26: =IF(K26=13,D25,"") | K26: =LEN(A26) -> 0 | L26: =IF(K26=13,LEFT(A26,7),"") | M26: =IF(AND(K26=13,D25="CAD"),ROUND(F26+H26,2),0) -> 0 | N26: =IF(AND(K26=13,D25="USD"),ROUND(G26+I26,2),0) -> 0 | O26: =IF(K26=13,IF(M26+N26=0,"Yes",0),0) -> 0 | P26: =IFERROR(VLOOKUP(B26,'Receivable Invoice Detail'!$S$1:$U$3014,3,FALSE),0) -> 0
A27: SO16476 Total | F27: 2121.09 | G27: 1473.6664 | H27: -2121.09 | I27: 0 | J27: =IF(K27=13,D26,"") -> CAD | K27: =LEN(A27) -> 13 | L27: =IF(K27=13,LEFT(A27,7),"") -> SO16476 | M27: =IF(AND(K27=13,D26="CAD"),ROUND(F27+H27,2),0) -> 0 | N27: =IF(AND(K27=13,D26="USD"),ROUND(G27+I27,2),0) -> 0 | O27: =IF(K27=13,IF(M27+N27=0,"Yes",0),0) -> Yes | P27: =IFERROR(VLOOKUP(B27,'Receivable Invoice Detail'!$S$1:$U$3014,3,FALSE),0) -> 0
A28: SO16496 | B28: INV12596 | C28: ProPart Pompes du Canada 9425-4380 Quebec Inc | D28: CAD | E28: Yes | F28: 9500.83 | G28: 6602.3191 | H28: -8614.85 | I28: 0 | J28: =IF(K28=13,D27,"") | K28: =LEN(A28) -> 7 | L28: =IF(K28=13,LEFT(A28,7),"") | M28: =IF(AND(K28=13,D27="CAD"),ROUND(F28+H28,2),0) -> 0 | N28: =IF(AND(K28=13,D27="USD"),ROUND(G28+I28,2),0) -> 0 | O28: =IF(K28=13,IF(M28+N28=0,"Yes",0),0) -> 0 | P28: =IFERROR(VLOOKUP(B28,'Receivable Invoice Detail'!$S$1:$U$3014,3,FALSE),0) -> 0
B29: INV12620 | C29: ProPart Pompes du Canada 9425-4380 Quebec Inc | D29: CAD | E29: Yes | F29: 0 | G29: 0 | H29: -885.98 | I29: 0 | J29: =IF(K29=13,D28,"") | K29: =LEN(A29) -> 0 | L29: =IF(K29=13,LEFT(A29,7),"") | M29: =IF(AND(K29=13,D28="CAD"),ROUND(F29+H29,2),0) -> 0 | N29: =IF(AND(K29=13,D28="USD"),ROUND(G29+I29,2),0) -> 0 | O29: =IF(K29=13,IF(M29+N29=0,"Yes",0),0) -> 0 | P29: =IFERROR(VLOOKUP(B29,'Receivable Invoice Detail'!$S$1:$U$3014,3,FALSE),0) -> 0
A30: SO16496 Total | F30: 9500.83 | G30: 6602.3191 | H30: -9500.83 | I30: 0 | J30: =IF(K30=13,D29,"") -> CAD | K30: =LEN(A30) -> 13 | L30: =IF(K30=13,LEFT(A30,7),"") -> SO16496 | M30: =IF(AND(K30=13,D29="CAD"),ROUND(F30+H30,2),0) -> 0 | N30: =IF(AND(K30=13,D29="USD"),ROUND(G30+I30,2),0) -> 0 | O30: =IF(K30=13,IF(M30+N30=0,"Yes",0),0) -> Yes | P30: =IFERROR(VLOOKUP(B30,'Receivable Invoice Detail'!$S$1:$U$3014,3,FALSE),0) -> 0
A31: SO16501 | B31: INV12581 | C31: Grant Aggregate | D31: CAD | E31: Yes | F31: 0 | G31: 0 | H31: -7811.79 | I31: 0 | J31: =IF(K31=13,D30,"") | K31: =LEN(A31) -> 7 | L31: =IF(K31=13,LEFT(A31,7),"") | M31: =IF(AND(K31=13,D30="CAD"),ROUND(F31+H31,2),0) -> 0 | N31: =IF(AND(K31=13,D30="USD"),ROUND(G31+I31,2),0) -> 0 | O31: =IF(K31=13,IF(M31+N31=0,"Yes",0),0) -> 0 | P31: =IFERROR(VLOOKUP(B31,'Receivable Invoice Detail'!$S$1:$U$3014,3,FALSE),0) -> 0
B32: RINV/2025/00001 (Reversal of: INV12581) | C32: Grant Aggregate | D32: CAD | E32: Pend | F32: 5908.82 | G32: 4104.7279 | H32: 0 | I32: 0 | J32: =IF(K32=13,D31,"") | K32: =LEN(A32) -> 0 | L32: =IF(K32=13,LEFT(A32,7),"") | M32: =IF(AND(K32=13,D31="CAD"),ROUND(F32+H32,2),0) -> 0 | N32: =IF(AND(K32=13,D31="USD"),ROUND(G32+I32,2),0) -> 0 | O32: =IF(K32=13,IF(M32+N32=0,"Yes",0),0) -> 0 | P32: =IFERROR(VLOOKUP(B32,'Receivable Invoice Detail'!$S$1:$U$3014,3,FALSE),0) -> 0
A33: SO16501 Total | F33: 5908.82 | G33: 4104.7279 | H33: -7811.79 | I33: 0 | J33: =IF(K33=13,D32,"") -> CAD | K33: =LEN(A33) -> 13 | L33: =IF(K33=13,LEFT(A33,7),"") -> SO16501 | M33: =IF(AND(K33=13,D32="CAD"),ROUND(F33+H33,2),0) -> -1902.97 | N33: =IF(AND(K33=13,D32="USD"),ROUND(G33+I33,2),0) -> 0 | O33: =IF(K33=13,IF(M33+N33=0,"Yes",0),0) -> 0 | P33: =IFERROR(VLOOKUP(B33,'Receivable Invoice Detail'!$S$1:$U$3014,3,FALSE),0) -> 0
A34: SO16513 | B34: INV12833 | C34: Les Pompes du St-Laurent Inc. | D34: CAD | E34: Yes | F34: 0 | G34: 0 | H34: -10755.87 | I34: 0 | J34: =IF(K34=13,D33,"") | K34: =LEN(A34) -> 7 | L34: =IF(K34=13,LEFT(A34,7),"") | M34: =IF(AND(K34=13,D33="CAD"),ROUND(F34+H34,2),0) -> 0 | N34: =IF(AND(K34=13,D33="USD"),ROUND(G34+I34,2),0) -> 0 | O34: =IF(K34=13,IF(M34+N34=0,"Yes",0),0) -> 0 | P34: =IFERROR(VLOOKUP(B34,'Receivable Invoice Detail'!$S$1:$U$3014,3,FALSE),0) -> 0
B35: INV12915 | C35: Les Pompes du St-Laurent Inc. | D35: CAD | E35: Yes | F35: 16754.72 | G35: 11673.945 | H35: -5998.85 | I35: 0 | J35: =IF(K35=13,D34,"") | K35: =LEN(A35) -> 0 | L35: =IF(K35=13,LEFT(A35,7),"") | M35: =IF(AND(K35=13,D34="CAD"),ROUND(F35+H35,2),0) -> 0 | N35: =IF(AND(K35=13,D34="USD"),ROUND(G35+I35,2),0) -> 0 | O35: =IF(K35=13,IF(M35+N35=0,"Yes",0),0) -> 0 | P35: =IFERROR(VLOOKUP(B35,'Receivable Invoice Detail'!$S$1:$U$3014,3,FALSE),0) -> 0
A36: SO16513 Total | F36: 16754.72 | G36: 11673.945 | H36: -16754.72 | I36: 0 | J36: =IF(K36=13,D35,"") -> CAD | K36: =LEN(A36) -> 13 | L36: =IF(K36=13,LEFT(A36,7),"") -> SO16513 | M36: =IF(AND(K36=13,D35="CAD"),ROUND(F36+H36,2),0) -> 0 | N36: =IF(AND(K36=13,D35="USD"),ROUND(G36+I36,2),0) -> 0 | O36: =IF(K36=13,IF(M36+N36=0,"Yes",0),0) -> Yes | P36: =IFERROR(VLOOKUP(B36,'Receivable Invoice Detail'!$S$1:$U$3014,3,FALSE),0) -> 0
A37: SO16515 | B37: INV12615 | C37: Canadian Bearings Ltd. | D37: CAD | E37: Yes | F37: 1387.4 | G37: 950.22184 | H37: -158.34 | I37: 0 | J37: =IF(K37=13,D36,"") | K37: =LEN(A37) -> 7 | L37: =IF(K37=13,LEFT(A37,7),"") | M37: =IF(AND(K37=13,D36="CAD"),ROUND(F37+H37,2),0) -> 0 | N37: =IF(AND(K37=13,D36="USD"),ROUND(G37+I37,2),0) -> 0 | O37: =IF(K37=13,IF(M37+N37=0,"Yes",0),0) -> 0 | P37: =IFERROR(VLOOKUP(B37,'Receivable Invoice Detail'!$S$1:$U$3014,3,FALSE),0) -> 0
B38: INV12676 | C38: Canadian Bearings Ltd. | D38: CAD | E38: Yes | F38: 0 | G38: 0 | H38: -1229.06 | I38: 0 | J38: =IF(K38=13,D37,"") | K38: =LEN(A38) -> 0 | L38: =IF(K38=13,LEFT(A38,7),"") | M38: =IF(AND(K38=13,D37="CAD"),ROUND(F38+H38,2),0) -> 0 | N38: =IF(AND(K38=13,D37="USD"),ROUND(G38+I38,2),0) -> 0 | O38: =IF(K38=13,IF(M38+N38=0,"Yes",0),0) -> 0 | P38: =IFERROR(VLOOKUP(B38,'Receivable Invoice Detail'!$S$1:$U$3014,3,FALSE),0) -> 0
A39: SO16515 Total | F39: 1387.4 | G39: 950.22184 | H39: -1387.4 | I39: 0 | J39: =IF(K39=13,D38,"") -> CAD | K39: =LEN(A39) -> 13 | L39: =IF(K39=13,LEFT(A39,7),"") -> SO16515 | M39: =IF(AND(K39=13,D38="CAD"),ROUND(F39+H39,2),0) -> 0 | N39: =IF(AND(K39=13,D38="USD"),ROUND(G39+I39,2),0) -> 0 | O39: =IF(K39=13,IF(M39+N39=0,"Yes",0),0) -> Yes | P39: =IFERROR(VLOOKUP(B39,'Receivable Invoice Detail'!$S$1:$U$3014,3,FALSE),0) -> 0
A40: SO16516 | B40: INV12638 | C40: Canadian Bearings Ltd. | D40: CAD | E40: Yes | F40: 183.84 | G40: 128.48035 | H40: -126.5 | I40: 0 | J40: =IF(K40=13,D39,"") | K40: =LEN(A40) -> 7 | L40: =IF(K40=13,LEFT(A40,7),"") | M40: =IF(AND(K40=13,D39="CAD"),ROUND(F40+H40,2),0) -> 0 | N40: =IF(AND(K40=13,D39="USD"),ROUND(G40+I40,2),0) -> 0 | O40: =IF(K40=13,IF(M40+N40=0,"Yes",0),0) -> 0 | P40: =IFERROR(VLOOKUP(B40,'Receivable Invoice Detail'!$S$1:$U$3014,3,FALSE),0) -> 0
B41: INV12675 | C41: Canadian Bearings Ltd. | D41: CAD | E41: Yes | F41: 0 | G41: 0 | H41: -57.34 | I41: 0 | J41: =IF(K41=13,D40,"") | K41: =LEN(A41) -> 0 | L41: =IF(K41=13,LEFT(A41,7),"") | M41: =IF(AND(K41=13,D40="CAD"),ROUND(F41+H41,2),0) -> 0 | N41: =IF(AND(K41=13,D40="USD"),ROUND(G41+I41,2),0) -> 0 | O41: =IF(K41=13,IF(M41+N41=0,"Yes",0),0) -> 0 | P41: =IFERROR(VLOOKUP(B41,'Receivable Invoice Detail'!$S$1:$U$3014,3,FALSE),0) -> 0
...

Sheet CASOPOInvCL
A1: Número de facturas | B1: Referencia de la orden | C1: Reference | D1: Facturas | E1: Cliente | F1: Fecha de creación | G1: Fecha de la orden | H1: Shipping Date | I1: Vendedor | J1: Divisa | K1: Tasa de divisa | L1: Total CAD | M1: Total MXP | N1: Total USD | O1: Importe sin impuestos | P1: Impuestos | Q1: Total | R1: Delivery Status | S1: Hubspot Deal Owner | T1: Cant de Fact | U1: Month Created | V1: Year Created | W1: Month Paid | X1: Year Paid | Y1: Rate 1 | Z1: SO | AA1: SODate | AB1: INV | AC1: INVStatus | AD1: Date Paid | AE1: PO | AF1: Client | AG1: Curr | AH1: Odoo CAD | AI1: Odoo USA | AJ1: Rate 2 | AK1: Xero CAD | AL1: Xero USD | AM1: Dif CAD | AN1: Dif USD | AO1: Paid | AP1: Zero | AQ1: One | AR1: Two | AS1: Fully Paid | AT1: Delivered | AU1: TO be Paid | AV1: Freight | AW1: Commissionable amount in USD
A2: 1 | B2: SO16348 | C2: 6500015792 | D2: INV12491 | E2: Wesdome Gold Mines Ltd - Eagle River Mine | F2: 45659.4 | G2: 45663.596 | H2: 45664 | I2: Ian Trottier | J2: CAD | K2: 1 | L2: 20655.24 | M2: 0 | N2: 14381.876 | O2: 18278.97 | P2: 2376.27 | Q2: 20655.24 | R2: Delivered | T2: =IF(A2="",T1,A2) -> 1 | U2: =IF(F2="",U1,MONTH(F2)) -> 1 | V2: =IF(F2="",V1,YEAR(F2)) -> 2025 | W2: =IF(AC2="Paid",MONTH(AD2),"") -> 2 | X2: =IF(AC2="Paid",YEAR(AD2),"") -> 2025 | Y2: =IF(C2="",Y1,N2/L2) -> 0.69628222 | Z2: =IF(B2="",Z1,B2) -> SO16348 | AA2: =IF(F2="",AA1,F2) -> 45659.4 | AB2: =IF(D2="","No Inv",D2) -> INV12491 | AC2: =IFERROR(VLOOKUP(D2,CAARStatus!$A$2:$AA$1600,22,FALSE),"Not invoiced") -> Paid | AD2: =IF(AC2="Paid",IFERROR(VLOOKUP(D2,CAARStatus!$A$2:$AA$1600,6,FALSE),"Pending"),"Pending") -> 45692 | AE2: =IF(C2="",AE1,C2) -> 6500015792 | AF2: =IF(E2="",AF1,E2) -> Wesdome Gold Mines Ltd - Eagle River Mine | AG2: =IF(J2="",AG1,J2) -> CAD | AH2: =IFERROR(IF(AG2="CAD",O2,O2/K2),0) -> 18278.97 | AI2: =IF(L2-N2=0,VLOOKUP(U2,rate!A$4:B$15,2,FALSE)*AH2,IF(AG2="USD",O2,AH2*Y2)) -> 12727.322 | AJ2: =IFERROR(AI2/AH2,0) -> 0.69628222 | AK2: =-IF(AG2="CAD",IFERROR(VLOOKUP(D2,CAARStatus!$A$1:$Y$1600,16,FALSE),0),0) -> -18278.97 | AL2: =-IF(AG2="USD",IFERROR(VLOOKUP(D2,CAARStatus!$A$1:$Y$1600,11,FALSE),0),0) -> 0 | AM2: =IF(AG2="CAD",AH2+AK2,"") -> 0 | AN2: =IF(AG2="USD",AI2+AL2,"") | AO2: =IF(AC2="Paid","Yes","Pend") -> Yes | AP2: =IF(AND(AO2="Pend",T2<2),"Pend",IF(T2=1,"Yes","XX")) -> Yes | AQ2: =IFERROR(VLOOKUP(B2,InvBal!$L$4:$P$600,4,FALSE),"Pend") -> Pend | AR2: =IFERROR(VLOOKUP(D2,Manual!$C$1:$E$22,2,FALSE),"Pend") -> Pend | AS2: =IF(OR(AP2="Yes",AQ2="Yes",AR2="Yes"),"Yes","") -> Yes | AT2: =IF(R2="Delivered","Yes","") -> Yes | AU2: =IF(AND(AS2="Yes",AT2="Yes"),"Yes","") -> Yes | AV2: =IFERROR(VLOOKUP(D2,'Receivable Invoice Detail'!$S$1:$U$3014,3,FALSE),0) -> 0 | AW2: =IF(AU2="Yes",AI2-AV2,0) -> 12727.322
A3: 1 | B3: SO16349 | C3: 2243313 | D3: INV12951 | E3: Zijin Mining - Rosebel Goldmines N.V. | F3: 45659.435 | G3: 45660.647 | H3: 45815 | I3: Amanda Qiao | J3: USD | K3: 0.69331656 | L3: 16788.291 | M3: 0 | N3: 11639.6 | O3: 11639.6 | Q3: 11639.6 | R3: Delivered | T3: =IF(A3="",T2,A3) -> 1 | U3: =IF(F3="",U2,MONTH(F3)) -> 1 | V3: =IF(F3="",V2,YEAR(F3)) -> 2025 | W3: =IF(AC3="Paid",MONTH(AD3),"") -> 7 | X3: =IF(AC3="Paid",YEAR(AD3),"") -> 2025 | Y3: =IF(C3="",Y2,N3/L3) -> 0.69331656 | Z3: =IF(B3="",Z2,B3) -> SO16349 | AA3: =IF(F3="",AA2,F3) -> 45659.435 | AB3: =IF(D3="","No Inv",D3) -> INV12951 | AC3: =IFERROR(VLOOKUP(D3,CAARStatus!$A$2:$AA$1600,22,FALSE),"Not invoiced") -> Paid | AD3: =IF(AC3="Paid",IFERROR(VLOOKUP(D3,CAARStatus!$A$2:$AA$1600,6,FALSE),"Pending"),"Pending") -> 45849 | AE3: =IF(C3="",AE2,C3) -> 2243313 | AF3: =IF(E3="",AF2,E3) -> Zijin Mining - Rosebel Goldmines N.V. | AG3: =IF(J3="",AG2,J3) -> USD | AH3: =IFERROR(IF(AG3="CAD",O3,O3/K3),0) -> 16788.291 | AI3: =IF(L3-N3=0,VLOOKUP(U3,rate!A$4:B$15,2,FALSE)*AH3,IF(AG3="USD",O3,AH3*Y3)) -> 11639.6 | AJ3: =IFERROR(AI3/AH3,0) -> 0.69331656 | AK3: =-IF(AG3="CAD",IFERROR(VLOOKUP(D3,CAARStatus!$A$1:$Y$1600,16,FALSE),0),0) -> 0 | AL3: =-IF(AG3="USD",IFERROR(VLOOKUP(D3,CAARStatus!$A$1:$Y$1600,11,FALSE),0),0) -> -11639.6 | AM3: =IF(AG3="CAD",AH3+AK3,"") | AN3: =IF(AG3="USD",AI3+AL3,"") -> 0 | AO3: =IF(AC3="Paid","Yes","Pend") -> Yes | AP3: =IF(AND(AO3="Pend",T3<2),"Pend",IF(T3=1,"Yes","XX")) -> Yes | AQ3: =IFERROR(VLOOKUP(Z3,InvBal!$L$4:$P$600,4,FALSE),"Pend") -> Pend | AR3: =IFERROR(VLOOKUP(D3,Manual!$C$1:$E$22,2,FALSE),"Pend") -> Pend | AS3: =IF(OR(AP3="Yes",AQ3="Yes",AR3="Yes"),"Yes","") -> Yes | AT3: =IF(R3="Delivered","Yes","") -> Yes | AU3: =IF(AND(AS3="Yes",AT3="Yes"),"Yes","") -> Yes | AV3: =IFERROR(VLOOKUP(D3,'Receivable Invoice Detail'!$S$1:$U$3014,3,FALSE),0) -> 0 | AW3: =IF(AU3="Yes",AI3-AV3,0) -> 11639.6
A4: 1 | B4: SO16350 | C4: 4560061462 | D4: INV12497 | E4: Alamos Gold Inc, Alamos Gold Inc Island Gold Division | F4: 45659.437 | G4: 45659.439 | H4: 45670 | I4: Ian Trottier | J4: CAD | K4: 1 | L4: 1540.6 | M4: 0 | N4: 1068.1235 | O4: 1363.36 | P4: 177.24 | Q4: 1540.6 | R4: Delivered | T4: =IF(A4="",T3,A4) -> 1 | U4: =IF(F4="",U3,MONTH(F4)) -> 1 | V4: =IF(F4="",V3,YEAR(F4)) -> 2025 | W4: =IF(AC4="Paid",MONTH(AD4),"") -> 2 | X4: =IF(AC4="Paid",YEAR(AD4),"") -> 2025 | Y4: =IF(C4="",Y3,N4/L4) -> 0.69331656 | Z4: =IF(B4="",Z3,B4) -> SO16350 | AA4: =IF(F4="",AA3,F4) -> 45659.437 | AB4: =IF(D4="","No Inv",D4) -> INV12497 | AC4: =IFERROR(VLOOKUP(D4,CAARStatus!$A$2:$AA$1600,22,FALSE),"Not invoiced") -> Paid | AD4: =IF(AC4="Paid",IFERROR(VLOOKUP(D4,CAARStatus!$A$2:$AA$1600,6,FALSE),"Pending"),"Pending") -> 45698 | AE4: =IF(C4="",AE3,C4) -> 4560061462 | AF4: =IF(E4="",AF3,E4) -> Alamos Gold Inc, Alamos Gold Inc Island Gold Division | AG4: =IF(J4="",AG3,J4) -> CAD | AH4: =IFERROR(IF(AG4="CAD",O4,O4/K4),0) -> 1363.36 | AI4: =IF(L4-N4=0,VLOOKUP(U4,rate!A$4:B$15,2,FALSE)*AH4,IF(AG4="USD",O4,AH4*Y4)) -> 945.24006 | AJ4: =IFERROR(AI4/AH4,0) -> 0.69331656 | AK4: =-IF(AG4="CAD",IFERROR(VLOOKUP(D4,CAARStatus!$A$1:$Y$1600,16,FALSE),0),0) -> -1363.36 | AL4: =-IF(AG4="USD",IFERROR(VLOOKUP(D4,CAARStatus!$A$1:$Y$1600,11,FALSE),0),0) -> 0 | AM4: =IF(AG4="CAD",AH4+AK4,"") -> 0 | AN4: =IF(AG4="USD",AI4+AL4,"") | AO4: =IF(AC4="Paid","Yes","Pend") -> Yes | AP4: =IF(AND(AO4="Pend",T4<2),"Pend",IF(T4=1,"Yes","XX")) -> Yes | AQ4: =IFERROR(VLOOKUP(Z4,InvBal!$L$4:$P$600,4,FALSE),"Pend") -> Pend | AR4: =IFERROR(VLOOKUP(D4,Manual!$C$1:$E$22,2,FALSE),"Pend") -> Pend | AS4: =IF(OR(AP4="Yes",AQ4="Yes",AR4="Yes"),"Yes","") -> Yes | AT4: =IF(R4="Delivered","Yes","") -> Yes | AU4: =IF(AND(AS4="Yes",AT4="Yes"),"Yes","") -> Yes | AV4: =IFERROR(VLOOKUP(D4,'Receivable Invoice Detail'!$S$1:$U$3014,3,FALSE),0) -> 0 | AW4: =IF(AU4="Yes",AI4-AV4,0) -> 945.24006
A5: 1 | B5: SO16353 | C5: PO-007646 | D5: INV12591 | E5: Sling-Choker Manufacturing - Timmins | F5: 45659.574 | G5: 45659.707 | H5: 45673 | I5: Ian Trottier | J5: CAD | K5: 1 | L5: 2369.71 | M5: 0 | N5: 1642.9592 | O5: 2097.09 | P5: 272.62 | Q5: 2369.71 | R5: Delivered | T5: =IF(A5="",T4,A5) -> 1 | U5: =IF(F5="",U4,MONTH(F5)) -> 1 | V5: =IF(F5="",V4,YEAR(F5)) -> 2025 | W5: =IF(AC5="Paid",MONTH(AD5),"") -> 2 | X5: =IF(AC5="Paid",YEAR(AD5),"") -> 2025 | Y5: =IF(C5="",Y4,N5/L5) -> 0.69331656 | Z5: =IF(B5="",Z4,B5) -> SO16353 | AA5: =IF(F5="",AA4,F5) -> 45659.574 | AB5: =IF(D5="","No Inv",D5) -> INV12591 | AC5: =IFERROR(VLOOKUP(D5,CAARStatus!$A$2:$AA$1600,22,FALSE),"Not invoiced") -> Paid | AD5: =IF(AC5="Paid",IFERROR(VLOOKUP(D5,CAARStatus!$A$2:$AA$1600,6,FALSE),"Pending"),"Pending") -> 45707 | AE5: =IF(C5="",AE4,C5) -> PO-007646 | AF5: =IF(E5="",AF4,E5) -> Sling-Choker Manufacturing - Timmins | AG5: =IF(J5="",AG4,J5) -> CAD | AH5: =IFERROR(IF(AG5="CAD",O5,O5/K5),0) -> 2097.09 | AI5: =IF(L5-N5=0,VLOOKUP(U5,rate!A$4:B$15,2,FALSE)*AH5,IF(AG5="USD",O5,AH5*Y5)) -> 1453.9472 | AJ5: =IFERROR(AI5/AH5,0) -> 0.69331656 | AK5: =-IF(AG5="CAD",IFERROR(VLOOKUP(D5,CAARStatus!$A$1:$Y$1600,16,FALSE),0),0) -> -2097.09 | AL5: =-IF(AG5="USD",IFERROR(VLOOKUP(D5,CAARStatus!$A$1:$Y$1600,11,FALSE),0),0) -> 0 | AM5: =IF(AG5="CAD",AH5+AK5,"") -> 0 | AN5: =IF(AG5="USD",AI5+AL5,"") | AO5: =IF(AC5="Paid","Yes","Pend") -> Yes | AP5: =IF(AND(AO5="Pend",T5<2),"Pend",IF(T5=1,"Yes","XX")) -> Yes | AQ5: =IFERROR(VLOOKUP(Z5,InvBal!$L$4:$P$600,4,FALSE),"Pend") -> Pend | AR5: =IFERROR(VLOOKUP(D5,Manual!$C$1:$E$22,2,FALSE),"Pend") -> Pend | AS5: =IF(OR(AP5="Yes",AQ5="Yes",AR5="Yes"),"Yes","") -> Yes | AT5: =IF(R5="Delivered","Yes","") -> Yes | AU5: =IF(AND(AS5="Yes",AT5="Yes"),"Yes","") -> Yes | AV5: =IFERROR(VLOOKUP(D5,'Receivable Invoice Detail'!$S$1:$U$3014,3,FALSE),0) -> 0 | AW5: =IF(AU5="Yes",AI5-AV5,0) -> 1453.9472
A6: 1 | B6: SO16359 | C6: 5334612 | D6: INV12502 | E6: Corrosion Fluid Products Corp., Corrosion Fluid Products Corp. - Chicago | F6: 45663.493 | G6: 45664.592 | H6: 45665 | I6: Ian Trottier | J6: USD | K6: 0.69628222 | L6: 144.20877 | M6: 0 | N6: 100.41 | O6: 100.41 | Q6: 100.41 | R6: Delivered | T6: =IF(A6="",T5,A6) -> 1 | U6: =IF(F6="",U5,MONTH(F6)) -> 1 | V6: =IF(F6="",V5,YEAR(F6)) -> 2025 | W6: =IF(AC6="Paid",MONTH(AD6),"") -> 2 | X6: =IF(AC6="Paid",YEAR(AD6),"") -> 2025 | Y6: =IF(C6="",Y5,N6/L6) -> 0.69628222 | Z6: =IF(B6="",Z5,B6) -> SO16359 | AA6: =IF(F6="",AA5,F6) -> 45663.493 | AB6: =IF(D6="","No Inv",D6) -> INV12502 | AC6: =IFERROR(VLOOKUP(D6,CAARStatus!$A$2:$AA$1600,22,FALSE),"Not invoiced") -> Paid | AD6: =IF(AC6="Paid",IFERROR(VLOOKUP(D6,CAARStatus!$A$2:$AA$1600,6,FALSE),"Pending"),"Pending") -> 45701 | AE6: =IF(C6="",AE5,C6) -> 5334612 | AF6: =IF(E6="",AF5,E6) -> Corrosion Fluid Products Corp., Corrosion Fluid Products Corp. - Chicago | AG6: =IF(J6="",AG5,J6) -> USD | AH6: =IFERROR(IF(AG6="CAD",O6,O6/K6),0) -> 144.20877 | AI6: =IF(L6-N6=0,VLOOKUP(U6,rate!A$4:B$15,2,FALSE)*AH6,IF(AG6="USD",O6,AH6*Y6)) -> 100.41 | AJ6: =IFERROR(AI6/AH6,0) -> 0.69628222 | AK6: =-IF(AG6="CAD",IFERROR(VLOOKUP(D6,CAARStatus!$A$1:$Y$1600,16,FALSE),0),0) -> 0 | AL6: =-IF(AG6="USD",IFERROR(VLOOKUP(D6,CAARStatus!$A$1:$Y$1600,11,FALSE),0),0) -> -100.41 | AM6: =IF(AG6="CAD",AH6+AK6,"") | AN6: =IF(AG6="USD",AI6+AL6,"") -> 0 | AO6: =IF(AC6="Paid","Yes","Pend") -> Yes | AP6: =IF(AND(AO6="Pend",T6<2),"Pend",IF(T6=1,"Yes","XX")) -> Yes | AQ6: =IFERROR(VLOOKUP(Z6,InvBal!$L$4:$P$600,4,FALSE),"Pend") -> Pend | AR6: =IFERROR(VLOOKUP(D6,Manual!$C$1:$E$22,2,FALSE),"Pend") -> Pend | AS6: =IF(OR(AP6="Yes",AQ6="Yes",AR6="Yes"),"Yes","") -> Yes | AT6: =IF(R6="Delivered","Yes","") -> Yes | AU6: =IF(AND(AS6="Yes",AT6="Yes"),"Yes","") -> Yes | AV6: =IFERROR(VLOOKUP(D6,'Receivable Invoice Detail'!$S$1:$U$3014,3,FALSE),0) -> 0 | AW6: =IF(AU6="Yes",AI6-AV6,0) -> 100.41
A7: 1 | B7: SO16360 | C7: 6633 | D7: INV12492 | E7: Hyperflo | F7: 45663.509 | G7: 45663.583 | H7: 45664 | I7: Ian Trottier | J7: CAD | K7: 1 | L7: 1006.02 | M7: 0 | N7: 700.47384 | O7: 958.11 | P7: 47.91 | Q7: 1006.02 | R7: Delivered | T7: =IF(A7="",T6,A7) -> 1 | U7: =IF(F7="",U6,MONTH(F7)) -> 1 | V7: =IF(F7="",V6,YEAR(F7)) -> 2025 | W7: =IF(AC7="Paid",MONTH(AD7),"") -> 2 | X7: =IF(AC7="Paid",YEAR(AD7),"") -> 2025 | Y7: =IF(C7="",Y6,N7/L7) -> 0.69628222 | Z7: =IF(B7="",Z6,B7) -> SO16360 | AA7: =IF(F7="",AA6,F7) -> 45663.509 | AB7: =IF(D7="","No Inv",D7) -> INV12492 | AC7: =IFERROR(VLOOKUP(D7,CAARStatus!$A$2:$AA$1600,22,FALSE),"Not invoiced") -> Paid | AD7: =IF(AC7="Paid",IFERROR(VLOOKUP(D7,CAARStatus!$A$2:$AA$1600,6,FALSE),"Pending"),"Pending") -> 45709 | AE7: =IF(C7="",AE6,C7) -> 6633 | AF7: =IF(E7="",AF6,E7) -> Hyperflo | AG7: =IF(J7="",AG6,J7) -> CAD | AH7: =IFERROR(IF(AG7="CAD",O7,O7/K7),0) -> 958.11 | AI7: =IF(L7-N7=0,VLOOKUP(U7,rate!A$4:B$15,2,FALSE)*AH7,IF(AG7="USD",O7,AH7*Y7)) -> 667.11496 | AJ7: =IFERROR(AI7/AH7,0) -> 0.69628222 | AK7: =-IF(AG7="CAD",IFERROR(VLOOKUP(D7,CAARStatus!$A$1:$Y$1600,16,FALSE),0),0) -> -958.11 | AL7: =-IF(AG7="USD",IFERROR(VLOOKUP(D7,CAARStatus!$A$1:$Y$1600,11,FALSE),0),0) -> 0 | AM7: =IF(AG7="CAD",AH7+AK7,"") -> 0 | AN7: =IF(AG7="USD",AI7+AL7,"") | AO7: =IF(AC7="Paid","Yes","Pend") -> Yes | AP7: =IF(AND(AO7="Pend",T7<2),"Pend",IF(T7=1,"Yes","XX")) -> Yes | AQ7: =IFERROR(VLOOKUP(Z7,InvBal!$L$4:$P$600,4,FALSE),"Pend") -> Pend | AR7: =IFERROR(VLOOKUP(D7,Manual!$C$1:$E$22,2,FALSE),"Pend") -> Pend | AS7: =IF(OR(AP7="Yes",AQ7="Yes",AR7="Yes"),"Yes","") -> Yes | AT7: =IF(R7="Delivered","Yes","") -> Yes | AU7: =IF(AND(AS7="Yes",AT7="Yes"),"Yes","") -> Yes | AV7: =IFERROR(VLOOKUP(D7,'Receivable Invoice Detail'!$S$1:$U$3014,3,FALSE),0) -> 0 | AW7: =IF(AU7="Yes",AI7-AV7,0) -> 667.11496
A8: 1 | B8: SO16361 | C8: 007673 | D8: INV12901 | E8: Sling-Choker Manufacturing - Timmins | F8: 45663.524 | G8: 45673.552 | H8: 45750 | I8: Ian Trottier | J8: CAD | K8: 1 | L8: 29994.38 | M8: 0 | N8: 20856.609 | O8: 26543.7 | P8: 3450.68 | Q8: 29994.38 | R8: Delivered | T8: =IF(A8="",T7,A8) -> 1 | U8: =IF(F8="",U7,MONTH(F8)) -> 1 | V8: =IF(F8="",V7,YEAR(F8)) -> 2025 | W8: =IF(AC8="Paid",MONTH(AD8),"") -> 5 | X8: =IF(AC8="Paid",YEAR(AD8),"") -> 2025 | Y8: =IF(C8="",Y7,N8/L8) -> 0.69535056 | Z8: =IF(B8="",Z7,B8) -> SO16361 | AA8: =IF(F8="",AA7,F8) -> 45663.524 | AB8: =IF(D8="","No Inv",D8) -> INV12901 | AC8: =IFERROR(VLOOKUP(D8,CAARStatus!$A$2:$AA$1600,22,FALSE),"Not invoiced") -> Paid | AD8: =IF(AC8="Paid",IFERROR(VLOOKUP(D8,CAARStatus!$A$2:$AA$1600,6,FALSE),"Pending"),"Pending") -> 45798 | AE8: =IF(C8="",AE7,C8) -> 007673 | AF8: =IF(E8="",AF7,E8) -> Sling-Choker Manufacturing - Timmins | AG8: =IF(J8="",AG7,J8) -> CAD | AH8: =IFERROR(IF(AG8="CAD",O8,O8/K8),0) -> 26543.7 | AI8: =IF(L8-N8=0,VLOOKUP(U8,rate!A$4:B$15,2,FALSE)*AH8,IF(AG8="USD",O8,AH8*Y8)) -> 18457.177 | AJ8: =IFERROR(AI8/AH8,0) -> 0.69535056 | AK8: =-IF(AG8="CAD",IFERROR(VLOOKUP(D8,CAARStatus!$A$1:$Y$1600,16,FALSE),0),0) -> -26543.7 | AL8: =-IF(AG8="USD",IFERROR(VLOOKUP(D8,CAARStatus!$A$1:$Y$1600,11,FALSE),0),0) -> 0 | AM8: =IF(AG8="CAD",AH8+AK8,"") -> 0 | AN8: =IF(AG8="USD",AI8+AL8,"") | AO8: =IF(AC8="Paid","Yes","Pend") -> Yes | AP8: =IF(AND(AO8="Pend",T8<2),"Pend",IF(T8=1,"Yes","XX")) -> Yes | AQ8: =IFERROR(VLOOKUP(Z8,InvBal!$L$4:$P$600,4,FALSE),"Pend") -> Pend | AR8: =IFERROR(VLOOKUP(D8,Manual!$C$1:$E$22,2,FALSE),"Pend") -> Pend | AS8: =IF(OR(AP8="Yes",AQ8="Yes",AR8="Yes"),"Yes","") -> Yes | AT8: =IF(R8="Delivered","Yes","") -> Yes | AU8: =IF(AND(AS8="Yes",AT8="Yes"),"Yes","") -> Yes | AV8: =IFERROR(VLOOKUP(D8,'Receivable Invoice Detail'!$S$1:$U$3014,3,FALSE),0) -> 0 | AW8: =IF(AU8="Yes",AI8-AV8,0) -> 18457.177
A9: 1 | B9: SO16362 | C9: P349617 | D9: INV12503 | E9: Covia Corp - Junction City | F9: 45663.531 | G9: 45664.582 | H9: 45665 | I9: Marlen Martinez | J9: CAD | K9: 1 | L9: 8795 | M9: 0 | N9: 6131.3693 | O9: 8795 | Q9: 8795 | R9: Delivered | T9: =IF(A9="",T8,A9) -> 1 | U9: =IF(F9="",U8,MONTH(F9)) -> 1 | V9: =IF(F9="",V8,YEAR(F9)) -> 2025 | W9: =IF(AC9="Paid",MONTH(AD9),"") -> 4 | X9: =IF(AC9="Paid",YEAR(AD9),"") -> 2025 | Y9: =IF(C9="",Y8,N9/L9) -> 0.69714261 | Z9: =IF(B9="",Z8,B9) -> SO16362 | AA9: =IF(F9="",AA8,F9) -> 45663.531 | AB9: =IF(D9="","No Inv",D9) -> INV12503 | AC9: =IFERROR(VLOOKUP(D9,CAARStatus!$A$2:$AA$1600,22,FALSE),"Not invoiced") -> Paid | AD9: =IF(AC9="Paid",IFERROR(VLOOKUP(D9,CAARStatus!$A$2:$AA$1600,6,FALSE),"Pending"),"Pending") -> 45754 | AE9: =IF(C9="",AE8,C9) -> P349617 | AF9: =IF(E9="",AF8,E9) -> Covia Corp - Junction City | AG9: =IF(J9="",AG8,J9) -> CAD | AH9: =IFERROR(IF(AG9="CAD",O9,O9/K9),0) -> 8795 | AI9: =IF(L9-N9=0,VLOOKUP(U9,rate!A$4:B$15,2,FALSE)*AH9,IF(AG9="USD",O9,AH9*Y9)) -> 6131.3693 | AJ9: =IFERROR(AI9/AH9,0) -> 0.69714261 | AK9: =-IF(AG9="CAD",IFERROR(VLOOKUP(D9,CAARStatus!$A$1:$Y$1600,16,FALSE),0),0) -> -12684.334 | AL9: =-IF(AG9="USD",IFERROR(VLOOKUP(D9,CAARStatus!$A$1:$Y$1600,11,FALSE),0),0) -> 0 | AM9: =IF(AG9="CAD",AH9+AK9,"") -> -3889.3339 | AN9: =IF(AG9="USD",AI9+AL9,"") | AO9: =IF(AC9="Paid","Yes","Pend") -> Yes | AP9: =IF(AND(AO9="Pend",T9<2),"Pend",IF(T9=1,"Yes","XX")) -> Yes | AQ9: =IFERROR(VLOOKUP(Z9,InvBal!$L$4:$P$600,4,FALSE),"Pend") -> Pend | AR9: =IFERROR(VLOOKUP(D9,Manual!$C$1:$E$22,2,FALSE),"Pend") -> Pend | AS9: =IF(OR(AP9="Yes",AQ9="Yes",AR9="Yes"),"Yes","") -> Yes | AT9: =IF(R9="Delivered","Yes","") -> Yes | AU9: =IF(AND(AS9="Yes",AT9="Yes"),"Yes","") -> Yes | AV9: =IFERROR(VLOOKUP(D9,'Receivable Invoice Detail'!$S$1:$U$3014,3,FALSE),0) -> 845 | AW9: =IF(AU9="Yes",AI9-AV9,0) -> 5286.3693
A10: 1 | B10: SO16363 | C10: 2961 | D10: INV12685 | E10: Les Pompes du St-Laurent Inc. | F10: 45663.564 | G10: 45663.565 | H10: 45698 | I10: Ian Trottier | J10: CAD | K10: 1 | L10: 1135.51 | M10: 0 | N10: 790.63542 | O10: 1081.44 | P10: 54.07 | Q10: 1135.51 | R10: Delivered | T10: =IF(A10="",T9,A10) -> 1 | U10: =IF(F10="",U9,MONTH(F10)) -> 1 | V10: =IF(F10="",V9,YEAR(F10)) -> 2025 | W10: =IF(AC10="Paid",MONTH(AD10),"") -> 4 | X10: =IF(AC10="Paid",YEAR(AD10),"") -> 2025 | Y10: =IF(C10="",Y9,N10/L10) -> 0.69628222 | Z10: =IF(B10="",Z9,B10) -> SO16363 | AA10: =IF(F10="",AA9,F10) -> 45663.564 | AB10: =IF(D10="","No Inv",D10) -> INV12685 | AC10: =IFERROR(VLOOKUP(D10,CAARStatus!$A$2:$AA$1600,22,FALSE),"Not invoiced") -> Paid | AD10: =IF(AC10="Paid",IFERROR(VLOOKUP(D10,CAARStatus!$A$2:$AA$1600,6,FALSE),"Pending"),"Pending") -> 45768 | AE10: =IF(C10="",AE9,C10) -> 2961 | AF10: =IF(E10="",AF9,E10) -> Les Pompes du St-Laurent Inc. | AG10: =IF(J10="",AG9,J10) -> CAD | AH10: =IFERROR(IF(AG10="CAD",O10,O10/K10),0) -> 1081.44 | AI10: =IF(L10-N10=0,VLOOKUP(U10,rate!A$4:B$15,2,FALSE)*AH10,IF(AG10="USD",O10,AH10*Y10)) -> 752.98744 | AJ10: =IFERROR(AI10/AH10,0) -> 0.69628222 | AK10: =-IF(AG10="CAD",IFERROR(VLOOKUP(D10,CAARStatus!$A$1:$Y$1600,16,FALSE),0),0) -> -1081.44 | AL10: =-IF(AG10="USD",IFERROR(VLOOKUP(D10,CAARStatus!$A$1:$Y$1600,11,FALSE),0),0) -> 0 | AM10: =IF(AG10="CAD",AH10+AK10,"") -> 0 | AN10: =IF(AG10="USD",AI10+AL10,"") | AO10: =IF(AC10="Paid","Yes","Pend") -> Yes | AP10: =IF(AND(AO10="Pend",T10<2),"Pend",IF(T10=1,"Yes","XX")) -> Yes | AQ10: =IFERROR(VLOOKUP(Z10,InvBal!$L$4:$P$600,4,FALSE),"Pend") -> Pend | AR10: =IFERROR(VLOOKUP(D10,Manual!$C$1:$E$22,2,FALSE),"Pend") -> Pend | AS10: =IF(OR(AP10="Yes",AQ10="Yes",AR10="Yes"),"Yes","") -> Yes | AT10: =IF(R10="Delivered","Yes","") -> Yes | AU10: =IF(AND(AS10="Yes",AT10="Yes"),"Yes","") -> Yes | AV10: =IFERROR(VLOOKUP(D10,'Receivable Invoice Detail'!$S$1:$U$3014,3,FALSE),0) -> 0 | AW10: =IF(AU10="Yes",AI10-AV10,0) -> 752.98744
A11: 1 | B11: SO16364 | C11: 003247 | D11: INV12837 | E11: Eleazar General & Industrial Supplies Limited | F11: 45663.57 | G11: 45667.613 | H11: 45751 | I11: Ian Trottier | J11: USD | K11: 0.69455773 | L11: 1896.8762 | M11: 0 | N11: 1317.49 | O11: 1317.49 | Q11: 1317.49 | R11: Delivered | T11: =IF(A11="",T10,A11) -> 1 | U11: =IF(F11="",U10,MONTH(F11)) -> 1 | V11: =IF(F11="",V10,YEAR(F11)) -> 2025 | W11: =IF(AC11="Paid",MONTH(AD11),"") -> 4 | X11: =IF(AC11="Paid",YEAR(AD11),"") -> 2025 | Y11: =IF(C11="",Y10,N11/L11) -> 0.69455773 | Z11: =IF(B11="",Z10,B11) -> SO16364 | AA11: =IF(F11="",AA10,F11) -> 45663.57 | AB11: =IF(D11="","No Inv",D11) -> INV12837 | AC11: =IFERROR(VLOOKUP(D11,CAARStatus!$A$2:$AA$1600,22,FALSE),"Not invoiced") -> Paid | AD11: =IF(AC11="Paid",IFERROR(VLOOKUP(D11,CAARStatus!$A$2:$AA$1600,6,FALSE),"Pending"),"Pending") -> 45754 | AE11: =IF(C11="",AE10,C11) -> 003247 | AF11: =IF(E11="",AF10,E11) -> Eleazar General & Industrial Supplies Limited | AG11: =IF(J11="",AG10,J11) -> USD | AH11: =IFERROR(IF(AG11="CAD",O11,O11/K11),0) -> 1896.8762 | AI11: =IF(L11-N11=0,VLOOKUP(U11,rate!A$4:B$15,2,FALSE)*AH11,IF(AG11="USD",O11,AH11*Y11)) -> 1317.49 | AJ11: =IFERROR(AI11/AH11,0) -> 0.69455773 | AK11: =-IF(AG11="CAD",IFERROR(VLOOKUP(D11,CAARStatus!$A$1:$Y$1600,16,FALSE),0),0) -> 0 | AL11: =-IF(AG11="USD",IFERROR(VLOOKUP(D11,CAARStatus!$A$1:$Y$1600,11,FALSE),0),0) -> -1317.49 | AM11: =IF(AG11="CAD",AH11+AK11,"") | AN11: =IF(AG11="USD",AI11+AL11,"") -> 0 | AO11: =IF(AC11="Paid","Yes","Pend") -> Yes | AP11: =IF(AND(AO11="Pend",T11<2),"Pend",IF(T11=1,"Yes","XX")) -> Yes | AQ11: =IFERROR(VLOOKUP(Z11,InvBal!$L$4:$P$600,4,FALSE),"Pend") -> Pend | AR11: =IFERROR(VLOOKUP(D11,Manual!$C$1:$E$22,2,FALSE),"Pend") -> Pend | AS11: =IF(OR(AP11="Yes",AQ11="Yes",AR11="Yes"),"Yes","") -> Yes | AT11: =IF(R11="Delivered","Yes","") -> Yes | AU11: =IF(AND(AS11="Yes",AT11="Yes"),"Yes","") -> Yes | AV11: =IFERROR(VLOOKUP(D11,'Receivable Invoice Detail'!$S$1:$U$3014,3,FALSE),0) -> 0 | AW11: =IF(AU11="Yes",AI11-AV11,0) -> 1317.49
A12: 1 | B12: SO16368 | C12: M-083469 | D12: INV12509 | E12: Grant Aggregate | F12: 45663.694 | G12: 45666.408 | H12: 45667 | I12: Ian Trottier | J12: CAD | K12: 1 | L12: 17048.1 | M12: 0 | N12: 11840.89 | O12: 15086.8 | P12: 1961.3 | Q12: 17048.1 | R12: Delivered | T12: =IF(A12="",T11,A12) -> 1 | U12: =IF(F12="",U11,MONTH(F12)) -> 1 | V12: =IF(F12="",V11,YEAR(F12)) -> 2025 | W12: =IF(AC12="Paid",MONTH(AD12),"") -> 3 | X12: =IF(AC12="Paid",YEAR(AD12),"") -> 2025 | Y12: =IF(C12="",Y11,N12/L12) -> 0.69455773 | Z12: =IF(B12="",Z11,B12) -> SO16368 | AA12: =IF(F12="",AA11,F12) -> 45663.694 | AB12: =IF(D12="","No Inv",D12) -> INV12509 | AC12: =IFERROR(VLOOKUP(D12,CAARStatus!$A$2:$AA$1600,22,FALSE),"Not invoiced") -> Paid | AD12: =IF(AC12="Paid",IFERROR(VLOOKUP(D12,CAARStatus!$A$2:$AA$1600,6,FALSE),"Pending"),"Pending") -> 45721 | AE12: =IF(C12="",AE11,C12) -> M-083469 | AF12: =IF(E12="",AF11,E12) -> Grant Aggregate | AG12: =IF(J12="",AG11,J12) -> CAD | AH12: =IFERROR(IF(AG12="CAD",O12,O12/K12),0) -> 15086.8 | AI12: =IF(L12-N12=0,VLOOKUP(U12,rate!A$4:B$15,2,FALSE)*AH12,IF(AG12="USD",O12,AH12*Y12)) -> 10478.654 | AJ12: =IFERROR(AI12/AH12,0) -> 0.69455773 | AK12: =-IF(AG12="CAD",IFERROR(VLOOKUP(D12,CAARStatus!$A$1:$Y$1600,16,FALSE),0),0) -> -15086.8 | AL12: =-IF(AG12="USD",IFERROR(VLOOKUP(D12,CAARStatus!$A$1:$Y$1600,11,FALSE),0),0) -> 0 | AM12: =IF(AG12="CAD",AH12+AK12,"") -> 0 | AN12: =IF(AG12="USD",AI12+AL12,"") | AO12: =IF(AC12="Paid","Yes","Pend") -> Yes | AP12: =IF(AND(AO12="Pend",T12<2),"Pend",IF(T12=1,"Yes","XX")) -> Yes | AQ12: =IFERROR(VLOOKUP(Z12,InvBal!$L$4:$P$600,4,FALSE),"Pend") -> Pend | AR12: =IFERROR(VLOOKUP(D12,Manual!$C$1:$E$22,2,FALSE),"Pend") -> Pend | AS12: =IF(OR(AP12="Yes",AQ12="Yes",AR12="Yes"),"Yes","") -> Yes | AT12: =IF(R12="Delivered","Yes","") -> Yes | AU12: =IF(AND(AS12="Yes",AT12="Yes"),"Yes","") -> Yes | AV12: =IFERROR(VLOOKUP(D12,'Receivable Invoice Detail'!$S$1:$U$3014,3,FALSE),0) -> 0 | AW12: =IF(AU12="Yes",AI12-AV12,0) -> 10478.654
A13: 1 | B13: SO16369 | C13: PO13146 | D13: INV12493 | E13: Manufacture Sling-Choker (Val-d’Or) Ltée | F13: 45664.409 | G13: 45664.622 | H13: 45665 | I13: Ian Trottier | J13: CAD | K13: 1 | L13: 117.99 | M13: 0 | N13: 82.255857 | O13: 112.37 | P13: 5.62 | Q13: 117.99 | R13: Delivered | T13: =IF(A13="",T12,A13) -> 1 | U13: =IF(F13="",U12,MONTH(F13)) -> 1 | V13: =IF(F13="",V12,YEAR(F13)) -> 2025 | W13: =IF(AC13="Paid",MONTH(AD13),"") -> 2 | X13: =IF(AC13="Paid",YEAR(AD13),"") -> 2025 | Y13: =IF(C13="",Y12,N13/L13) -> 0.69714261 | Z13: =IF(B13="",Z12,B13) -> SO16369 | AA13: =IF(F13="",AA12,F13) -> 45664.409 | AB13: =IF(D13="","No Inv",D13) -> INV12493 | AC13: =IFERROR(VLOOKUP(D13,CAARStatus!$A$2:$AA$1600,22,FALSE),"Not invoiced") -> Paid | AD13: =IF(AC13="Paid",IFERROR(VLOOKUP(D13,CAARStatus!$A$2:$AA$1600,6,FALSE),"Pending"),"Pending") -> 45693 | AE13: =IF(C13="",AE12,C13) -> PO13146 | AF13: =IF(E13="",AF12,E13) -> Manufacture Sling-Choker (Val-d’Or) Ltée | AG13: =IF(J13="",AG12,J13) -> CAD | AH13: =IFERROR(IF(AG13="CAD",O13,O13/K13),0) -> 112.37 | AI13: =IF(L13-N13=0,VLOOKUP(U13,rate!A$4:B$15,2,FALSE)*AH13,IF(AG13="USD",O13,AH13*Y13)) -> 78.337915 | AJ13: =IFERROR(AI13/AH13,0) -> 0.69714261 | AK13: =-IF(AG13="CAD",IFERROR(VLOOKUP(D13,CAARStatus!$A$1:$Y$1600,16,FALSE),0),0) -> -112.37 | AL13: =-IF(AG13="USD",IFERROR(VLOOKUP(D13,CAARStatus!$A$1:$Y$1600,11,FALSE),0),0) -> 0 | AM13: =IF(AG13="CAD",AH13+AK13,"") -> 0 | AN13: =IF(AG13="USD",AI13+AL13,"") | AO13: =IF(AC13="Paid","Yes","Pend") -> Yes | AP13: =IF(AND(AO13="Pend",T13<2),"Pend",IF(T13=1,"Yes","XX")) -> Yes | AQ13: =IFERROR(VLOOKUP(Z13,InvBal!$L$4:$P$600,4,FALSE),"Pend") -> Pend | AR13: =IFERROR(VLOOKUP(D13,Manual!$C$1:$E$22,2,FALSE),"Pend") -> Pend | AS13: =IF(OR(AP13="Yes",AQ13="Yes",AR13="Yes"),"Yes","") -> Yes | AT13: =IF(R13="Delivered","Yes","") -> Yes | AU13: =IF(AND(AS13="Yes",AT13="Yes"),"Yes","") -> Yes | AV13: =IFERROR(VLOOKUP(D13,'Receivable Invoice Detail'!$S$1:$U$3014,3,FALSE),0) -> 0 | AW13: =IF(AU13="Yes",AI13-AV13,0) -> 78.337915
A14: 1 | B14: SO16372 | C14: 2991 | D14: INV12779 | E14: Les Pompes du St-Laurent Inc. | F14: 45664.491 | G14: 45673.632 | H14: 45720 | I14: Ian Trottier | J14: CAD | K14: 1 | L14: 1657.93 | M14: 0 | N14: 1152.8426 | O14: 1578.98 | P14: 78.95 | Q14: 1657.93 | R14: Delivered | T14: =IF(A14="",T13,A14) -> 1 | U14: =IF(F14="",U13,MONTH(F14)) -> 1 | V14: =IF(F14="",V13,YEAR(F14)) -> 2025 | W14: =IF(AC14="Paid",MONTH(AD14),"") -> 4 | X14: =IF(AC14="Paid",YEAR(AD14),"") -> 2025 | Y14: =IF(C14="",Y13,N14/L14) -> 0.69535056 | Z14: =IF(B14="",Z13,B14) -> SO16372 | AA14: =IF(F14="",AA13,F14) -> 45664.491 | AB14: =IF(D14="","No Inv",D14) -> INV12779 | AC14: =IFERROR(VLOOKUP(D14,CAARStatus!$A$2:$AA$1600,22,FALSE),"Not invoiced") -> Paid | AD14: =IF(AC14="Paid",IFERROR(VLOOKUP(D14,CAARStatus!$A$2:$AA$1600,6,FALSE),"Pending"),"Pending") -> 45772 | AE14: =IF(C14="",AE13,C14) -> 2991 | AF14: =IF(E14="",AF13,E14) -> Les Pompes du St-Laurent Inc. | AG14: =IF(J14="",AG13,J14) -> CAD | AH14: =IFERROR(IF(AG14="CAD",O14,O14/K14),0) -> 1578.98 | AI14: =IF(L14-N14=0,VLOOKUP(U14,rate!A$4:B$15,2,FALSE)*AH14,IF(AG14="USD",O14,AH14*Y14)) -> 1097.9446 | AJ14: =IFERROR(AI14/AH14,0) -> 0.69535056 | AK14: =-IF(AG14="CAD",IFERROR(VLOOKUP(D14,CAARStatus!$A$1:$Y$1600,16,FALSE),0),0) -> -1578.98 | AL14: =-IF(AG14="USD",IFERROR(VLOOKUP(D14,CAARStatus!$A$1:$Y$1600,11,FALSE),0),0) -> 0 | AM14: =IF(AG14="CAD",AH14+AK14,"") -> 0 | AN14: =IF(AG14="USD",AI14+AL14,"") | AO14: =IF(AC14="Paid","Yes","Pend") -> Yes | AP14: =IF(AND(AO14="Pend",T14<2),"Pend",IF(T14=1,"Yes","XX")) -> Yes | AQ14: =IFERROR(VLOOKUP(Z14,InvBal!$L$4:$P$600,4,FALSE),"Pend") -> Pend | AR14: =IFERROR(VLOOKUP(D14,Manual!$C$1:$E$22,2,FALSE),"Pend") -> Pend | AS14: =IF(OR(AP14="Yes",AQ14="Yes",AR14="Yes"),"Yes","") -> Yes | AT14: =IF(R14="Delivered","Yes","") -> Yes | AU14: =IF(AND(AS14="Yes",AT14="Yes"),"Yes","") -> Yes | AV14: =IFERROR(VLOOKUP(D14,'Receivable Invoice Detail'!$S$1:$U$3014,3,FALSE),0) -> 0 | AW14: =IF(AU14="Yes",AI14-AV14,0) -> 1097.9446
